Workbook

Sheet guide

Sheet Ingredients
B2: Ingredient | C2: Weight | D2: Unit | E2: Packages/Case | F2: Supplier | G2: Current Cost | H2: Cost per oz/ea
B3: Protein
B4: Brisket | C4: 15 | D4: per lb | E4: 1 | F4: chef supply | G4: 4.99
B5: Pork Butt | C5: 20 | D5: per lb | E5: 1 | F5: chef supply | G5: 2.09
B6: Tri-tip | C6: 15 | D6: per lb | E6: 1 | F6: chef supply | G6: 6.79
B7: Chicken quarters | C7: 40 | D7: lb | E7: 1 | F7: chef supply | G7: 37.19
B9: Other ingredients
B10: Almond extract | C10: 16 | D10: oz | E10: 1 | F10: chef supply | G10: 7.39 | H10: =IF(D10="lb",G10/(C10*16),G10/C10) -> 0.461875
B11: Apple cider vinegar | C11: 128 | D11: oz | E11: 1 | F11: chef supply | G11: 5.89 | H11: =IF(D11="lb",G11/(C11*16),G11/C11) -> 0.046015625
B12: Baked beans | C12: 117 | D12: oz | E12: 6 | F12: chef supply | G12: 53.19 | H12: =G12/(C12*E12) -> 0.075769231
B13: Banana pudding mix | C13: 1 | D13: box | E13: 1 | G13: 1.97 | H13: =IF(D13="lb",G13/(C13*16),G13/C13) -> 1.97
B14: Proprietary Ingredient 5 | C14: 5 | D14: oz | E14: 1 | F14: chef supply | G14: 8.79 | H14: =IF(D14="lb",G14/(C14*16),G14/C14) -> 1.758
B15: Proprietary Ingredient 2 | C15: 18 | D15: oz | E15: 1 | F15: chef supply | G15: 25.69 | H15: =IF(D15="lb",G15/(C15*16),G15/C15) -> 1.4272222
B16: Brown Sugar | C16: 32 | D16: lb | E16: 32 | F16: chef supply | G16: 55.89 | H16: =G16/(C16*16) -> 0.10916016
B17: Butter | C17: 30 | D17: lb | E17: 30 | F17: chef supply | G17: 68.99 | H17: =IF(D17="lb",G17/(C17*16),G17/C17) -> 0.14372917
B18: Proprietary Ingredient 4 | C18: 8 | D18: oz | E18: 1 | G18: 7.99 | H18: =IF(D18="lb",G18/(C18*16),G18/C18) -> 0.99875
B19: Chili powder | C19: 18 | D19: =D14 -> oz | E19: 1 | F19: chef supply | G19: 13.79 | H19: =IF(D19="lb",G19/(C19*16),G19/C19) -> 0.76611111
B20: Coleslaw, Resers | C20: 112 | D20: oz | E20: 1 | F20: chef supply | G20: 18.79 | H20: =IF(D20="lb",G20/(C20*16),G20/C20) -> 0.16776786
B21: Corn Cobbetts | C21: 144 | D21: case | E21: (6) case | F21: chef supply | G21: 42.19 | H21: =SUM(G21/C21) -> 0.29298611
B22: Corn starch | C22: 16 | D22: oz | E22: 1 | F22: chef supply | G22: 2.79 | H22: =IF(D22="lb",G22/(C22*16),G22/C22) -> 0.174375
B23: Franz Hawaiian buns | D23: 12 | E23: 1 | F23: chef supply | G23: 4.99 | H23: =SUM(G23/D23) -> 0.41583333
B24: French fries | C24: 4.5 | D24: lb | E24: 6 | F24: chef supply | G24: 23.59 | H24: =IF(D24="lb",G24/(C24*E24*16),G24/C24) -> 0.054606481
B25: Frozen Blackberries | C25: 5 | D25: lb | E25: 1 | F25: chef supply | G25: 19.59 | H25: =IF(D25="lb",G25/(C25*16),G25/C25) -> 0.244875
B26: Proprietary Ingredient 1 | C26: 26 | D26: oz | E26: 1 | F26: chef supply | G26: 23.39 | H26: =IF(D26="lb",G26/(C26*16),G26/C26) -> 0.89961538
B27: Honey mustard | C27: 13 | D27: oz | E27: 1 | F27: chef supply | G27: 4.49 | H27: =IF(D27="lb",G27/(C27*16),G27/C27) -> 0.34538462
B28: Ketchup | C28: 114 | D28: oz | E28: 1 | F28: chef supply | G28: 13.79 | H28: =IF(D28="lb",G28/(C28*16),G28/C28) -> 0.12096491
B29: Krusteaz pankcake mix | C29: 5 | D29: lb | E29: 1 | F29: chef supply | G29: 7.39 | H29: =IF(D29="lb",G29/(C29*16),G29/C29) -> 0.092375
B30: Lemon juice | C30: 32 | D30: oz | E30: 1 | F30: chef supply | G30: 2.39 | H30: =IF(D30="lb",G30/(C30*16),G30/C30) -> 0.0746875
B31: Macaroni and cheese | C31: 40 | D31: oz | E31: 1 | F31: chef supply | G31: 13.79 | H31: =IF(D31="lb",G31/(C31*16),G31/C31) -> 0.34475
B32: Med cheddar, shredded | C32: 40 | D32: oz | E32: 1 | F32: chef supply | G32: 13.79 | H32: =IF(D32="lb",G32/(C32*16),G32/C32) -> 0.34475
B33: Milk | C33: 256 | D33: oz | E33: 1 | F33: chef supply | G33: 7.79 | H33: =IF(D33="lb",G33/(C33*16),G33/C33) -> 0.030429688
B34: Molasses | C34: 15 | D34: oz | E34: 1 | F34: Amazon | G34: 14.99 | H34: =IF(D34="lb",G34/(C34*16),G34/C34) -> 0.99933333
B35: Nilla wafer | C35: 14 | D35: box | E35: 1 | G35: 5.28 | H35: =IF(D35="lb",G35/(C35*16),G35/C35) -> 0.37714286
B36: Onion powder | C36: 18 | D36: =D31 -> oz | E36: 1 | F36: chef supply | G36: 13.09 | H36: =IF(D36="lb",G36/(C36*16),G36/C36) -> 0.72722222
B37: Proprietary Ingredient 3 | C37: 5.25 | D37: lb | E37: 1 | F37: chef supply | G37: 60.79 | H37: =IF(D37="lb",G37/(C37*16),G37/C37) -> 0.72369048
B38: Peach cubes | C38: 5 | D38: lb | E38: 1 | F38: chef supply | G38: 15.59 | H38: =IF(D38="lb",G38/(C38*16),G38/C38) -> 0.194875
B39: Pickling salt | C39: 4 | D39: lb | E39: 1 | F39: chef supply | G39: 3.39 | H39: =IF(D39="lb",G39/(C39*16),G39/C39) -> 0.05296875
B40: Potato Salad, Resers | C40: 128 | D40: oz | E40: 1 | F40: chef supply | G40: 15.69 | H40: =IF(D40="lb",G40/(C40*16),G40/C40) -> 0.12257812
B41: Proprietary Ingredient 6 | C41: 13 | D41: =D36 -> oz | E41: 1 | F41: chef supply | G41: 13.39 | H41: =IF(D41="lb",G41/(C41*16),G41/C41) -> 1.03
B42: Sugar | C42: 5 | D42: lb | E42: 1 | F42: chef supply | G42: 12.89 | H42: =IF(D42="lb",G42/(C42*16),G42/C42) -> 0.161125
...

Sheet Meat Prep
B2: Meat | C2: Raw Weight/lb | D2: Raw cost/lb | E2: Raw batch cost | F2: Yield % | G2: Finished weight/lb | H2: Rub Used/oz | I2: Rub cost | J2: Finished cost/lb
B3: Brisket | C3: 15 | D3: =_xlfn.LET( _xlpm.item,B3, _xlpm.unit,TRIM(_xlfn.XLOOKUP(_xlpm.item,Ingredients!$B:$B,Ingredients!$D:$D,"")), _xlpm.weight,_xlfn.XLOOKUP(_xlpm.item,Ingredients!$B:$B,Ingredients!$C:$C,""), _xlpm.cost,_xlfn.XLOOKUP(_xlpm.item,Ingredients!$B:$B,Ingredients!$G:$G,""), IF(_xlpm.unit="per lb",_xlpm.cost,IF(_xlpm.unit="lb",_xlpm.cost/_xlpm.weight,"")) ) -> 4.99 | E3: =SUM(C3*D3) -> 74.85 | F3: 0.6 | G3: =SUM(C3*F3) -> 9 | H3: 8 | I3: =H3*'Meat Recipes'!$F$16 -> 1.9712764 | J3: =SUM((E3+I3)/G3) -> 8.5356974
B4: Pork Butt | C4: 20 | D4: =_xlfn.LET( _xlpm.item,B4, _xlpm.unit,TRIM(_xlfn.XLOOKUP(_xlpm.item,Ingredients!$B:$B,Ingredients!$D:$D,"")), _xlpm.weight,_xlfn.XLOOKUP(_xlpm.item,Ingredients!$B:$B,Ingredients!$C:$C,""), _xlpm.cost,_xlfn.XLOOKUP(_xlpm.item,Ingredients!$B:$B,Ingredients!$G:$G,""), IF(_xlpm.unit="per lb",_xlpm.cost,IF(_xlpm.unit="lb",_xlpm.cost/_xlpm.weight,"")) ) -> 2.09 | E4: =SUM(C4*D4) -> 41.8 | F4: 0.68 | G4: =SUM(C4*F4) -> 13.6 | H4: 6 | I4: =H4*'Meat Recipes'!$F$16 -> 1.4784573 | J4: =SUM((E4+I4)/G4) -> 3.1822395
B5: Tri-tip | C5: 15 | D5: =_xlfn.LET( _xlpm.item,B5, _xlpm.unit,TRIM(_xlfn.XLOOKUP(_xlpm.item,Ingredients!$B:$B,Ingredients!$D:$D,"")), _xlpm.weight,_xlfn.XLOOKUP(_xlpm.item,Ingredients!$B:$B,Ingredients!$C:$C,""), _xlpm.cost,_xlfn.XLOOKUP(_xlpm.item,Ingredients!$B:$B,Ingredients!$G:$G,""), IF(_xlpm.unit="per lb",_xlpm.cost,IF(_xlpm.unit="lb",_xlpm.cost/_xlpm.weight,"")) ) -> 6.79 | E5: =SUM(C5*D5) -> 101.85 | F5: 0.75 | G5: =SUM(C5*F5) -> 11.25 | H5: 2 | I5: =H5*'Meat Recipes'!$F$16 -> 0.49281911 | J5: =SUM((E5+I5)/G5) -> 9.0971395
B6: Chicken quarters | C6: 40 | D6: =_xlfn.LET( _xlpm.item,B6, _xlpm.unit,TRIM(_xlfn.XLOOKUP(_xlpm.item,Ingredients!$B:$B,Ingredients!$D:$D,"")), _xlpm.weight,_xlfn.XLOOKUP(_xlpm.item,Ingredients!$B:$B,Ingredients!$C:$C,""), _xlpm.cost,_xlfn.XLOOKUP(_xlpm.item,Ingredients!$B:$B,Ingredients!$G:$G,""), IF(_xlpm.unit="per lb",_xlpm.cost,IF(_xlpm.unit="lb",_xlpm.cost/_xlpm.weight,"")) ) -> 0.92975 | E6: =SUM(C6*D6) -> 37.19 | F6: 1 | G6: =SUM(C6*F6) -> 40 | H6: 13 | I6: =H6*'Meat Recipes'!$F$16 -> 3.2033242 | J6: =SUM((E6+I6)/G6) -> 1.0098331

Sheet Meat Recipes
C3: #2 rub
C4: Ingredient | D4: Weight | E4: Unit | F4: cost
C5: Brown Sugar | D5: 64 | E5: oz | F5: =IFERROR(IF(E5="lb",D5*16,D5)*_xlfn.XLOOKUP(C5,Ingredients!$B:$B,Ingredients!$H:$H),"") -> 6.98625
C6: Pickling salt | D6: 8 | E6: oz | F6: =IFERROR(IF(E6="lb",D6*16,D6)*_xlfn.XLOOKUP(C6,Ingredients!$B:$B,Ingredients!$H:$H),"") -> 0.42375
C7: Onion powder | D7: 4 | E7: oz | F7: =IFERROR(IF(E7="lb",D7*16,D7)*_xlfn.XLOOKUP(C7,Ingredients!$B:$B,Ingredients!$H:$H),"") -> 2.9088889
C8: Chili powder | D8: 3 | E8: oz | F8: =IFERROR(IF(E8="lb",D8*16,D8)*_xlfn.XLOOKUP(C8,Ingredients!$B:$B,Ingredients!$H:$H),"") -> 2.2983333
C9: Proprietary Ingredient 1 | D9: 2.5 | E9: oz | F9: =IFERROR(IF(E9="lb",D9*16,D9)*_xlfn.XLOOKUP(C9,Ingredients!$B:$B,Ingredients!$H:$H),"") -> 2.2490385
C10: Proprietary Ingredient 2 | D10: 2 | E10: oz | F10: =IFERROR(IF(E10="lb",D10*16,D10)*_xlfn.XLOOKUP(C10,Ingredients!$B:$B,Ingredients!$H:$H),"") -> 2.8544444
C11: Proprietary Ingredient 3 | D11: 2 | E11: oz | F11: =IFERROR(IF(E11="lb",D11*16,D11)*_xlfn.XLOOKUP(C11,Ingredients!$B:$B,Ingredients!$H:$H),"") -> 1.447381
C12: Proprietary Ingredient 4 | D12: 1 | E12: oz | F12: =IFERROR(IF(E12="lb",D12*16,D12)*_xlfn.XLOOKUP(C12,Ingredients!$B:$B,Ingredients!$H:$H),"") -> 0.99875
C13: Proprietary Ingredient 5 | D13: 0.5 | E13: oz | F13: =IFERROR(IF(E13="lb",D13*16,D13)*_xlfn.XLOOKUP(C13,Ingredients!$B:$B,Ingredients!$H:$H),"") -> 0.879
C14: Proprietary Ingredient 6 | D14: 0.5 | E14: oz | F14: =IFERROR(IF(E14="lb",D14*16,D14)*_xlfn.XLOOKUP(C14,Ingredients!$B:$B,Ingredients!$H:$H),"") -> 0.515
C15: Total | D15: =SUM(D5:D14) -> 87.5 | F15: =SUM(F5:F14) -> 21.560836
C16: Cost per oz | F16: =SUM(F15/D15) -> 0.24640956
C18: #2 Rub Sauce
C19: Ingredient | D19: Weight | E19: Unit | F19: cost
C20: Ketchup | D20: 24 | E20: oz | F20: =IFERROR(IF(E20="lb",D20*16,D20)*_xlfn.XLOOKUP(C20,Ingredients!$B:$B,Ingredients!$H:$H),"") -> 2.9031579
C21: Apple cider vinegar | D21: 4 | E21: oz | F21: =IFERROR(IF(E21="lb",D21*16,D21)*_xlfn.XLOOKUP(C21,Ingredients!$B:$B,Ingredients!$H:$H),"") -> 0.1840625
C22: Water | D22: 8 | E22: oz | F22: =IFERROR(IF(E22="lb",D22*16,D22)*_xlfn.XLOOKUP(C22,Ingredients!$B:$B,Ingredients!$H:$H),"") -> 0
C23: Worcestershire | D23: 1 | E23: oz | F23: =IFERROR(IF(E23="lb",D23*16,D23)*_xlfn.XLOOKUP(C23,Ingredients!$B:$B,Ingredients!$H:$H),"") -> 0.22335937
C24: Honey mustard | D24: 2 | E24: oz | F24: =IFERROR(IF(E24="lb",D24*16,D24)*_xlfn.XLOOKUP(C24,Ingredients!$B:$B,Ingredients!$H:$H),"") -> 0.69076923
C25: #2 Rub | D25: 16 | E25: oz | F25: =SUM(D25*F16) -> 3.9425529
C26: Total | D26: =SUM(D20:D25) -> 55 | F26: =SUM(F20:F25) -> 7.9439019
C27: Cost Per oz | F27: =SUM(F26/D26) -> 0.14443458
C28: 2oz Sauce Cups | F28: =(F27*1.5)+_xlfn.XLOOKUP(Packaging!F7,Packaging!F7,Packaging!F7) -> 0.25093187

Sheet Other recipes
B2: Blackberry Cobbler | E2: 6 tins
B3: Ingredient | C3: Weight | D3: Unit | E3: Cost
B4: Frozen Blackberries | C4: 16 | D4: oz | E4: =C4*_xlfn.XLOOKUP(B4,Ingredients!$B$10:$B$49,Ingredients!$H$10:$H$49) -> 3.918
B5: Krusteaz pankcake mix | C5: 8 | D5: oz | E5: =C5*_xlfn.XLOOKUP(B5,Ingredients!$B$10:$B$49,Ingredients!$H$10:$H$49) -> 0.739
B6: Sugar | C6: 1 | D6: oz | E6: =C6*_xlfn.XLOOKUP(B6,Ingredients!$B$10:$B$49,Ingredients!$H$10:$H$49) -> 0.161125
B7: Almond extract | C7: 0.14 | D7: oz | E7: =C7*_xlfn.XLOOKUP(B7,Ingredients!$B$10:$B$49,Ingredients!$H$10:$H$49) -> 0.0646625
B8: Lemon juice | C8: 0.5 | D8: oz | E8: =C8*_xlfn.XLOOKUP(B8,Ingredients!$B$10:$B$49,Ingredients!$H$10:$H$49) -> 0.03734375
B9: Vanilla extract | C9: 0.14 | D9: oz | E9: =C9*_xlfn.XLOOKUP(B9,Ingredients!$B$10:$B$49,Ingredients!$H$10:$H$49) -> 0.0480375
B10: Water | C10: 10 | D10: oz | E10: =C10*_xlfn.XLOOKUP(B10,Ingredients!$B$10:$B$49,Ingredients!$H$10:$H$49) -> 0
B11: Corn starch | C11: 0.1 | D11: oz | E11: =C11*_xlfn.XLOOKUP(B11,Ingredients!$B$10:$B$49,Ingredients!$H$10:$H$49) -> 0.0174375
B12: 5oz tin for baking | C12: 6 | E12: =C12*_xlfn.XLOOKUP(Packaging!B3,Packaging!B3,Packaging!E3) -> 1.3314 | F12: Per cup
B13: Total | E13: =SUM(E4:E12) -> 6.3170063 | F13: =SUM(E13/C12) -> 1.0528344
B15: Peach Cobbler | E15: 6 tins
B16: Ingredient | C16: Weight | D16: Unit | E16: Cost
B17: Peach cubes | C17: 16 | D17: oz | E17: =C17*_xlfn.XLOOKUP(B17,Ingredients!$B$10:$B$49,Ingredients!$H$10:$H$49) -> 3.118
B18: Krusteaz pankcake mix | C18: 8 | D18: oz | E18: =C18*_xlfn.XLOOKUP(B18,Ingredients!$B$10:$B$49,Ingredients!$H$10:$H$49) -> 0.739
B19: Sugar | C19: 1 | D19: oz | E19: =C19*_xlfn.XLOOKUP(B19,Ingredients!$B$10:$B$49,Ingredients!$H$10:$H$49) -> 0.161125
B20: Almond extract | C20: 0.14 | D20: oz | E20: =C20*_xlfn.XLOOKUP(B20,Ingredients!$B$10:$B$49,Ingredients!$H$10:$H$49) -> 0.0646625
B21: Lemon juice | C21: 0.5 | D21: oz | E21: =C21*_xlfn.XLOOKUP(B21,Ingredients!$B$10:$B$49,Ingredients!$H$10:$H$49) -> 0.03734375
B22: Vanilla extract | C22: 0.14 | D22: oz | E22: =C22*_xlfn.XLOOKUP(B22,Ingredients!$B$10:$B$49,Ingredients!$H$10:$H$49) -> 0.0480375
B23: Water | C23: 10 | D23: oz | E23: =C23*_xlfn.XLOOKUP(B23,Ingredients!$B$10:$B$49,Ingredients!$H$10:$H$49) -> 0
B24: Corn starch | C24: 0.1 | D24: oz | E24: =C24*_xlfn.XLOOKUP(B24,Ingredients!$B$10:$B$49,Ingredients!$H$10:$H$49) -> 0.0174375
B25: Molasses | C25: 0.5 | D25: oz | E25: =C25*_xlfn.XLOOKUP(B25,Ingredients!$B$10:$B$49,Ingredients!$H$10:$H$49) -> 0.49966667
B26: 5oz tin for baking | C26: 6 | E26: =C26*_xlfn.XLOOKUP(Packaging!B3,Packaging!B3,Packaging!E3) -> 1.3314 | F26: Per cup
B27: Total | E27: =SUM(E17:E26) -> 6.0166729 | F27: =SUM(E27/C26) -> 1.0027788
B29: Banana Pudding | E29: 6 tins
B30: Ingredient | C30: Weight | D30: Unit | E30: Cost
B31: Banana pudding mix | C31: 1 | D31: 5oz box | E31: =C31*_xlfn.XLOOKUP(B31,Ingredients!$B$10:$B$49,Ingredients!$H$10:$H$49) -> 1.97
B32: Milk | C32: 24 | D32: oz | E32: =C32*_xlfn.XLOOKUP(B32,Ingredients!$B$10:$B$49,Ingredients!$H$10:$H$49) -> 0.7303125
B33: Nilla wafer | C33: 1 | D33: oz | E33: =C33*_xlfn.XLOOKUP(B33,Ingredients!$B$10:$B$49,Ingredients!$H$10:$H$49) -> 0.37714286
B34: 5oz tin for baking | C34: 6 | E34: =C34*_xlfn.XLOOKUP(Packaging!B3,Packaging!B3,Packaging!E3) -> 1.3314 | F34: Per cup
B35: Total | E35: =SUM(E31:E34) -> 4.4088554 | F35: =SUM(E35/C34) -> 0.73480923
B37: Loaded pulled pork fries
B38: Ingredient | C38: Weight | D38: Unit | E38: Cost
B39: Pork Butt | C39: 4 | D39: oz | E39: =_xlfn.XLOOKUP('Other recipes'!B39,'Meat Prep'!B4,'Meat Prep'!J4)*(C39/16) -> 0.79555988
B40: French fries | C40: 6 | D40: oz | E40: =C40*_xlfn.XLOOKUP(B40,Ingredients!B24,Ingredients!H24) -> 0.32763889
B41: Med cheddar, shredded | C41: 2 | D41: oz | E41: =_xlfn.XLOOKUP(B41,Ingredients!B32,Ingredients!H32)*C41 -> 0.6895
B44: Total | E44: =SUM(E39:E43) -> 1.8126988

Sheet Packaging
B2: Item | C2: Count | D2: Price | E2: Cost Each | F2: Combined
B3: 5oz tin ramekin | C3: 100 | D3: 22.19 | E3: =SUM(D3/C3) -> 0.2219
B4: 3 COMPARTMENT 8X8 INCH FIBER TO GO CONTAINER | C4: 100 | D4: 25.59 | E4: =SUM(D4/C4) -> 0.2559
B5: BAGCRAFT 12X12 WHITE WAX GREASE RESISTANT WAX PAPER | C5: 1000 | D5: 22.59 | E5: =SUM(D5/C5) -> 0.02259
B6: 2 OUNCE PORTION CUP | C6: 250 | D6: 4.99 | E6: =SUM(D6/C6) -> 0.01996
B7: DART PLASTIC CLEAR LID FOR 2 OZ PORTION CUP | C7: 125 | D7: 1.79 | E7: =SUM(D7/C7) -> 0.01432 | F7: =SUM(E6:E7) -> 0.03428
B8: SOUTHERN CHAMPION SOUTHLAND FOOD TRAY #300 5.375 X 3.375 X 2 INCH | C8: 250 | D8: 15.49 | E8: =SUM(D8/C8) -> 0.06196
B9: ECOSYSTEMS 9x6 MFPP BLACK HINGED CONTAINER | C9: 150 | D9: 24.79 | E9: =SUM(D9/C9) -> 0.16526667
B10: AJM METRO REUSABLE THANK YOU T-SHIRT BAG 11.5 X 6 X 21.6 | C10: 200 | D10: 18.29 | E10: =SUM(D10/C10) -> 0.09145
B11: VITAL ASSORTED CUTLERY WHITE PLASTIC HEAVY WEIGHT | C11: 288 | D11: 7.29 | E11: =SUM(D11/C11) -> 0.0253125

Sheet Menu items
B2: Menu Item | C2: Type | D2: Main Portion oz | E2: Main Cost | F2: Bun Qty | G2: Bun Cost | H2: Sauce oz | I2: Sauce Cost | J2: Side 1 | K2: Side 1 Cost | L2: Side 2 | M2: Side 2 cost | N2: Packaging Cost | O2: Total Cost
B3: Pulled Pork Sandwich | C3: Sandwich | D3: 6 | E3: =_xlfn.XLOOKUP("Pork Butt",'Meat Prep'!$B:$B,'Meat Prep'!$J:$J,"")*(D3/16) -> 1.1933398 | F3: 1 | G3: =F3*_xlfn.XLOOKUP("Franz Hawaiian buns",Ingredients!$B:$B,Ingredients!$H:$H,"") -> 0.41583333 | H3: 1 | I3: =H3*'Meat Recipes'!$F$27 -> 0.14443458 | J3: - | L3: - | N3: =_xlfn.XLOOKUP("BAGCRAFT 12X12 WHITE WAX GREASE RESISTANT WAX PAPER",Packaging!$B:$B,Packaging!$E:$E,"") -> 0.02259 | O3: =SUM(E3,G3,I3,N3) -> 1.7761977
B5: Pulled Pork Combo 1 | C5: Combo | D5: 6 | E5: =_xlfn.XLOOKUP("Pork Butt",'Meat Prep'!$B:$B,'Meat Prep'!$J:$J,"")*(D5/16) -> 1.1933398 | F5: 1 | G5: =F5*_xlfn.XLOOKUP("Franz Hawaiian buns",Ingredients!$B:$B,Ingredients!$H:$H,"") -> 0.41583333 | H5: 0 | I5: =H5*'Meat Recipes'!$F$27 -> 0 | J5: French fries | K5: =_xlfn.XLOOKUP(J5,$B$37:$B$45,$E$37:$E$45,"") -> 0.27303241 | M5: =_xlfn.XLOOKUP(L5,$B$37:$B$45,$E$37:$E$45,"") -> 0 | N5: =_xlfn.XLOOKUP(Packaging!E9,Packaging!E9,Packaging!E9) -> 0.16526667 | O5: =SUM(E5,G5,I5,K5,M5,N5) -> 2.0474722
B6: Pulled Pork Combo 2 | C6: Combo | D6: 6 | E6: =_xlfn.XLOOKUP("Pork Butt",'Meat Prep'!$B:$B,'Meat Prep'!$J:$J,"")*(D6/16) -> 1.1933398 | F6: 1 | G6: =F6*_xlfn.XLOOKUP("Franz Hawaiian buns",Ingredients!$B:$B,Ingredients!$H:$H,"") -> 0.41583333 | H6: 0 | I6: =H6*'Meat Recipes'!$F$27 -> 0 | J6: Potato Salad, Resers | K6: =_xlfn.XLOOKUP(J6,$B$37:$B$45,$E$37:$E$45,"") -> 0.73546875 | L6: Baked beans | M6: =_xlfn.XLOOKUP(L6,$B$37:$B$45,$E$37:$E$45,"") -> 0.45461538 | N6: =_xlfn.XLOOKUP(Packaging!B4,Packaging!B4,Packaging!E4) -> 0.2559 | O6: =SUM(E6,G6,I6,K6,M6,N6) -> 3.0551573
B7: Pulled Pork Combo 3 | C7: Combo | D7: 6 | E7: =_xlfn.XLOOKUP("Pork Butt",'Meat Prep'!$B:$B,'Meat Prep'!$J:$J,"")*(D7/16) -> 1.1933398 | F7: 1 | G7: =F7*_xlfn.XLOOKUP("Franz Hawaiian buns",Ingredients!$B:$B,Ingredients!$H:$H,"") -> 0.41583333 | H7: 0 | I7: =H7*'Meat Recipes'!$F$27 -> 0 | J7: Corn Cobbetts | K7: =_xlfn.XLOOKUP(J7,$B$37:$B$45,$E$37:$E$45,"") -> 0.29298611 | L7: Baked beans | M7: =_xlfn.XLOOKUP(L7,$B$37:$B$45,$E$37:$E$45,"") -> 0.45461538 | N7: =_xlfn.XLOOKUP(Packaging!B4,Packaging!B4,Packaging!E4) -> 0.2559 | O7: =SUM(E7,G7,I7,K7,M7,N7) -> 2.6126746
B8: Pulled Pork Combo 4 | C8: Combo | D8: 6 | E8: =_xlfn.XLOOKUP("Pork Butt",'Meat Prep'!$B:$B,'Meat Prep'!$J:$J,"")*(D8/16) -> 1.1933398 | F8: 1 | G8: =F8*_xlfn.XLOOKUP("Franz Hawaiian buns",Ingredients!$B:$B,Ingredients!$H:$H,"") -> 0.41583333 | I8: =H8*'Meat Recipes'!$F$27 -> 0 | J8: French fries | K8: =_xlfn.XLOOKUP(J8,$B$37:$B$45,$E$37:$E$45,"") -> 0.27303241 | L8: Coleslaw, Resers | M8: =_xlfn.XLOOKUP(L8,$B$37:$B$45,$E$37:$E$45,"") -> 1.0066071 | N8: =_xlfn.XLOOKUP(Packaging!B4,Packaging!B4,Packaging!E4) -> 0.2559 | O8: =SUM(E8,G8,I8,K8,M8,N8) -> 3.1447127
B9: Pulled Pork Plate 1 | C9: Plate | D9: 8 | E9: =_xlfn.XLOOKUP("Pork Butt",'Meat Prep'!$B:$B,'Meat Prep'!$J:$J,"")*(D9/16) -> 1.5911198 | H9: 2 | I9: =H9*'Meat Recipes'!$F$27 -> 0.28886916 | J9: Potato Salad, Resers | K9: =_xlfn.XLOOKUP(J9,$B$37:$B$45,$E$37:$E$45,"") -> 0.73546875 | L9: French fries | M9: =_xlfn.XLOOKUP(L9,$B$37:$B$45,$E$37:$E$45,"") -> 0.27303241 | N9: =_xlfn.XLOOKUP(Packaging!B4,Packaging!B4,Packaging!E4) -> 0.2559 | O9: =SUM(E9,G9,I9,K9,M9,N9) -> 3.1443901
B10: Pulled Pork Plate 2 | C10: Plate | D10: 8 | E10: =_xlfn.XLOOKUP("Pork Butt",'Meat Prep'!$B:$B,'Meat Prep'!$J:$J,"")*(D10/16) -> 1.5911198 | H10: 2 | I10: =H10*'Meat Recipes'!$F$27 -> 0.28886916 | J10: Potato Salad, Resers | K10: =_xlfn.XLOOKUP(J10,$B$37:$B$45,$E$37:$E$45,"") -> 0.73546875 | L10: Baked beans | M10: =_xlfn.XLOOKUP(L10,$B$37:$B$45,$E$37:$E$45,"") -> 0.45461538 | N10: =_xlfn.XLOOKUP(Packaging!B4,Packaging!B4,Packaging!E4) -> 0.2559 | O10: =SUM(E10,G10,I10,K10,M10,N10) -> 3.325973
B11: Pulled Pork Plate 3 | C11: Plate | D11: 8 | E11: =_xlfn.XLOOKUP("Pork Butt",'Meat Prep'!$B:$B,'Meat Prep'!$J:$J,"")*(D11/16) -> 1.5911198 | H11: 2 | I11: =H11*'Meat Recipes'!$F$27 -> 0.28886916 | J11: Macaroni and cheese | K11: =_xlfn.XLOOKUP(J11,$B$37:$B$45,$E$37:$E$45,"") -> 1.72375 | L11: Baked beans | M11: =_xlfn.XLOOKUP(L11,$B$37:$B$45,$E$37:$E$45,"") -> 0.45461538 | N11: =_xlfn.XLOOKUP(Packaging!B4,Packaging!B4,Packaging!E4) -> 0.2559 | O11: =SUM(E11,G11,I11,K11,M11,N11) -> 4.3142543
B12: Pulled Pork Plate 4 | C12: Plate | D12: 8 | E12: =_xlfn.XLOOKUP("Pork Butt",'Meat Prep'!$B:$B,'Meat Prep'!$J:$J,"")*(D12/16) -> 1.5911198 | H12: 2 | I12: =H12*'Meat Recipes'!$F$27 -> 0.28886916 | J12: French fries | K12: =_xlfn.XLOOKUP(J12,$B$37:$B$45,$E$37:$E$45,"") -> 0.27303241 | L12: Coleslaw, Resers | M12: =_xlfn.XLOOKUP(L12,$B$37:$B$45,$E$37:$E$45,"") -> 1.0066071 | N12: =_xlfn.XLOOKUP(Packaging!B4,Packaging!B4,Packaging!E4) -> 0.2559 | O12: =SUM(E12,G12,I12,K12,M12,N12) -> 3.4155285
B14: Loaded Pork Fries | C14: Specialty | E14: =_xlfn.XLOOKUP('Other recipes'!E44,'Other recipes'!E44,'Other recipes'!E44) -> 1.8126988 | H14: 2 | I14: =H14*'Meat Recipes'!$F$27 -> 0.28886916 | N14: =_xlfn.XLOOKUP(Packaging!E8,Packaging!E8,Packaging!E8) -> 0.06196 | O14: =SUM(E14,G14,I14,K14,M14,N14) -> 2.1635279
B16: Brisket Sandwich | C16: Sandwich | D16: 6 | E16: =_xlfn.XLOOKUP("Brisket",'Meat Prep'!$B:$B,'Meat Prep'!$J:$J,"")*(D16/16) -> 3.2008865 | F16: 1 | G16: =F16*_xlfn.XLOOKUP("Franz Hawaiian buns",Ingredients!$B:$B,Ingredients!$H:$H,"") -> 0.41583333 | H16: 0 | I16: =H16*'Meat Recipes'!$F$27 -> 0 | N16: =_xlfn.XLOOKUP("BAGCRAFT 12X12 WHITE WAX GREASE RESISTANT WAX PAPER",Packaging!$B:$B,Packaging!$E:$E,"") -> 0.02259 | O16: =SUM(E16,G16,I16,K16,M16,N16) -> 3.6393099
B18: Brisket Combo 1 | C18: Combo | D18: 6 | E18: =_xlfn.XLOOKUP("Brisket",'Meat Prep'!$B:$B,'Meat Prep'!$J:$J,"")*(D18/16) -> 3.2008865 | F18: 1 | G18: =F18*_xlfn.XLOOKUP("Franz Hawaiian buns",Ingredients!$B:$B,Ingredients!$H:$H,"") -> 0.41583333 | H18: 0 | I18: =H18*'Meat Recipes'!$F$27 -> 0 | J18: French fries | K18: =_xlfn.XLOOKUP(J18,$B$37:$B$45,$E$37:$E$45,"") -> 0.27303241 | M18: =_xlfn.XLOOKUP(L18,$B$37:$B$45,$E$37:$E$45,"") -> 0 | N18: =_xlfn.XLOOKUP(Packaging!E9,Packaging!E9,Packaging!E9) -> 0.16526667 | O18: =SUM(E18,G18,I18,K18,M18,N18) -> 4.0550189
B19: Brisket Combo 2 | C19: Combo | D19: 6 | E19: =_xlfn.XLOOKUP("Brisket",'Meat Prep'!$B:$B,'Meat Prep'!$J:$J,"")*(D19/16) -> 3.2008865 | F19: 1 | G19: =F19*_xlfn.XLOOKUP("Franz Hawaiian buns",Ingredients!$B:$B,Ingredients!$H:$H,"") -> 0.41583333 | H19: 0 | I19: =H19*'Meat Recipes'!$F$27 -> 0 | J19: Potato Salad, Resers | K19: =_xlfn.XLOOKUP(J19,$B$37:$B$45,$E$37:$E$45,"") -> 0.73546875 | L19: Baked beans | M19: =_xlfn.XLOOKUP(L19,$B$37:$B$45,$E$37:$E$45,"") -> 0.45461538 | N19: =_xlfn.XLOOKUP(Packaging!B4,Packaging!B4,Packaging!E4) -> 0.2559 | O19: =SUM(E19,G19,I19,K19,M19,N19) -> 5.062704
B20: Brisket Combo 3 | C20: Combo | D20: 6 | E20: =_xlfn.XLOOKUP("Brisket",'Meat Prep'!$B:$B,'Meat Prep'!$J:$J,"")*(D20/16) -> 3.2008865 | F20: 1 | G20: =F20*_xlfn.XLOOKUP("Franz Hawaiian buns",Ingredients!$B:$B,Ingredients!$H:$H,"") -> 0.41583333 | H20: 0 | I20: =H20*'Meat Recipes'!$F$27 -> 0 | J20: Macaroni and cheese | K20: =_xlfn.XLOOKUP(J20,$B$37:$B$45,$E$37:$E$45,"") -> 1.72375 | L20: Baked beans | M20: =_xlfn.XLOOKUP(L20,$B$37:$B$45,$E$37:$E$45,"") -> 0.45461538 | N20: =_xlfn.XLOOKUP(Packaging!B4,Packaging!B4,Packaging!E4) -> 0.2559 | O20: =SUM(E20,G20,I20,K20,M20,N20) -> 6.0509852
B21: Brisket Combo 4 | C21: Combo | D21: 6 | E21: =_xlfn.XLOOKUP("Brisket",'Meat Prep'!$B:$B,'Meat Prep'!$J:$J,"")*(D21/16) -> 3.2008865 | F21: 1 | G21: =F21*_xlfn.XLOOKUP("Franz Hawaiian buns",Ingredients!$B:$B,Ingredients!$H:$H,"") -> 0.41583333 | H21: 0 | I21: =H21*'Meat Recipes'!$F$27 -> 0 | J21: French fries | K21: =_xlfn.XLOOKUP(J21,$B$37:$B$45,$E$37:$E$45,"") -> 0.27303241 | L21: Coleslaw, Resers | M21: =_xlfn.XLOOKUP(L21,$B$37:$B$45,$E$37:$E$45,"") -> 1.0066071 | N21: =_xlfn.XLOOKUP(Packaging!B4,Packaging!B4,Packaging!E4) -> 0.2559 | O21: =SUM(E21,G21,I21,K21,M21,N21) -> 5.1522594
B22: Brisket Plate 1 | C22: Plate | D22: 8 | E22: =_xlfn.XLOOKUP("Brisket",'Meat Prep'!$B:$B,'Meat Prep'!$J:$J,"")*(D22/16) -> 4.2678487 | H22: 1 | I22: =H22*'Meat Recipes'!$F$27 -> 0.14443458 | J22: French fries | K22: =_xlfn.XLOOKUP(J22,$B$37:$B$45,$E$37:$E$45,"") -> 0.27303241 | L22: Potato Salad, Resers | M22: =_xlfn.XLOOKUP(L22,$B$37:$B$45,$E$37:$E$45,"") -> 0.73546875 | N22: =_xlfn.XLOOKUP(Packaging!B4,Packaging!B4,Packaging!E4) -> 0.2559 | O22: =SUM(E22,G22,I22,K22,M22,N22) -> 5.6766844
B23: Brisket Plate 2 | C23: Plate | D23: 8 | E23: =_xlfn.XLOOKUP("Brisket",'Meat Prep'!$B:$B,'Meat Prep'!$J:$J,"")*(D23/16) -> 4.2678487 | H23: 1 | I23: =H23*'Meat Recipes'!$F$27 -> 0.14443458 | J23: Potato Salad, Resers | K23: =_xlfn.XLOOKUP(J23,$B$37:$B$45,$E$37:$E$45,"") -> 0.73546875 | L23: Baked beans | M23: =_xlfn.XLOOKUP(L23,$B$37:$B$45,$E$37:$E$45,"") -> 0.45461538 | N23: =_xlfn.XLOOKUP(Packaging!B4,Packaging!B4,Packaging!E4) -> 0.2559 | O23: =SUM(E23,G23,I23,K23,M23,N23) -> 5.8582674
B24: Brisket Plate 3 | C24: Plate | D24: 8 | E24: =_xlfn.XLOOKUP("Brisket",'Meat Prep'!$B:$B,'Meat Prep'!$J:$J,"")*(D24/16) -> 4.2678487 | H24: 1 | I24: =H24*'Meat Recipes'!$F$27 -> 0.14443458 | J24: Macaroni and cheese | K24: =_xlfn.XLOOKUP(J24,$B$37:$B$45,$E$37:$E$45,"") -> 1.72375 | L24: Baked beans | M24: =_xlfn.XLOOKUP(L24,$B$37:$B$45,$E$37:$E$45,"") -> 0.45461538 | N24: =_xlfn.XLOOKUP(Packaging!B4,Packaging!B4,Packaging!E4) -> 0.2559 | O24: =SUM(E24,G24,I24,K24,M24,N24) -> 6.8465487
B25: Brisket Plate 4 | C25: Plate | D25: 8 | E25: =_xlfn.XLOOKUP("Brisket",'Meat Prep'!$B:$B,'Meat Prep'!$J:$J,"")*(D25/16) -> 4.2678487 | H25: 1 | I25: =H25*'Meat Recipes'!$F$27 -> 0.14443458 | J25: French fries | K25: =_xlfn.XLOOKUP(J25,$B$37:$B$45,$E$37:$E$45,"") -> 0.27303241 | L25: Coleslaw, Resers | M25: =_xlfn.XLOOKUP(L25,$B$37:$B$45,$E$37:$E$45,"") -> 1.0066071 | N25: =_xlfn.XLOOKUP(Packaging!B4,Packaging!B4,Packaging!E4) -> 0.2559 | O25: =SUM(E25,G25,I25,K25,M25,N25) -> 5.9478228
B27: Tri-tip Plate 1 | C27: Plate | D27: 6 | E27: =_xlfn.XLOOKUP('Meat Prep'!J5,'Meat Prep'!J5,'Meat Prep'!J5)*(D27/16) -> 3.4114273 | H27: 1 | I27: =H27*'Meat Recipes'!$F$27 -> 0.14443458 | J27: French fries | K27: =_xlfn.XLOOKUP(J27,$B$37:$B$45,$E$37:$E$45,"") -> 0.27303241 | L27: Potato Salad, Resers | M27: =_xlfn.XLOOKUP(L27,$B$37:$B$45,$E$37:$E$45,"") -> 0.73546875 | N27: =_xlfn.XLOOKUP(Packaging!B4,Packaging!B4,Packaging!E4) -> 0.2559 | O27: =SUM(E27,G27,I27,K27,M27,N27) -> 4.820263
B28: Tri-tip Plate 2 | C28: Plate | D28: 6 | E28: =_xlfn.XLOOKUP('Meat Prep'!J5,'Meat Prep'!J5,'Meat Prep'!J5)*(D28/16) -> 3.4114273 | H28: 1 | I28: =H28*'Meat Recipes'!$F$27 -> 0.14443458 | J28: Potato Salad, Resers | K28: =_xlfn.XLOOKUP(J28,$B$37:$B$45,$E$37:$E$45,"") -> 0.73546875 | L28: Baked beans | M28: =_xlfn.XLOOKUP(L28,$B$37:$B$45,$E$37:$E$45,"") -> 0.45461538 | N28: =_xlfn.XLOOKUP(Packaging!B4,Packaging!B4,Packaging!E4) -> 0.2559 | O28: =SUM(E28,G28,I28,K28,M28,N28) -> 5.001846
B29: Tri-tip Plate 3 | C29: Plate | D29: 6 | E29: =_xlfn.XLOOKUP('Meat Prep'!J5,'Meat Prep'!J5,'Meat Prep'!J5)*(D29/16) -> 3.4114273 | H29: 1 | I29: =H29*'Meat Recipes'!$F$27 -> 0.14443458 | J29: Macaroni and cheese | K29: =_xlfn.XLOOKUP(J29,$B$37:$B$45,$E$37:$E$45,"") -> 1.72375 | L29: Baked beans | M29: =_xlfn.XLOOKUP(L29,$B$37:$B$45,$E$37:$E$45,"") -> 0.45461538 | N29: =_xlfn.XLOOKUP(Packaging!B4,Packaging!B4,Packaging!E4) -> 0.2559 | O29: =SUM(E29,G29,I29,K29,M29,N29) -> 5.9901273
B30: Tri-tip Plate 4 | C30: Plate | D30: 6 | E30: =_xlfn.XLOOKUP('Meat Prep'!J5,'Meat Prep'!J5,'Meat Prep'!J5)*(D30/16) -> 3.4114273 | H30: 1 | I30: =H30*'Meat Recipes'!$F$27 -> 0.14443458 | J30: French fries | K30: =_xlfn.XLOOKUP(J30,$B$37:$B$45,$E$37:$E$45,"") -> 0.27303241 | L30: Coleslaw, Resers | M30: =_xlfn.XLOOKUP(L30,$B$37:$B$45,$E$37:$E$45,"") -> 1.0066071 | N30: =_xlfn.XLOOKUP(Packaging!B4,Packaging!B4,Packaging!E4) -> 0.2559 | O30: =SUM(E30,G30,I30,K30,M30,N30) -> 5.0914014
B32: Chicken quarters 1 | C32: Plate | D32: 10 | E32: =_xlfn.XLOOKUP('Meat Prep'!J6,'Meat Prep'!J6,'Meat Prep'!J6)*(D32/16) -> 0.63114569 | H32: 2 | I32: =H32*'Meat Recipes'!$F$27 -> 0.28886916 | J32: French fries | K32: =_xlfn.XLOOKUP(J32,$B$37:$B$45,$E$37:$E$45,"") -> 0.27303241 | L32: Potato Salad, Resers | M32: =_xlfn.XLOOKUP(L32,$B$37:$B$45,$E$37:$E$45,"") -> 0.73546875 | N32: =_xlfn.XLOOKUP(Packaging!B4,Packaging!B4,Packaging!E4) -> 0.2559 | O32: =SUM(E32,G32,I32,K32,M32,N32) -> 2.184416
B33: Chicken quarters 2 | C33: Plate | D33: 10 | E33: =_xlfn.XLOOKUP('Meat Prep'!J6,'Meat Prep'!J6,'Meat Prep'!J6)*(D33/16) -> 0.63114569 | H33: 2 | I33: =H33*'Meat Recipes'!$F$27 -> 0.28886916 | J33: Potato Salad, Resers | K33: =_xlfn.XLOOKUP(J33,$B$37:$B$45,$E$37:$E$45,"") -> 0.73546875 | L33: Baked beans | M33: =_xlfn.XLOOKUP(L33,$B$37:$B$45,$E$37:$E$45,"") -> 0.45461538 | N33: =_xlfn.XLOOKUP(Packaging!B4,Packaging!B4,Packaging!E4) -> 0.2559 | O33: =SUM(E33,G33,I33,K33,M33,N33) -> 2.365999
B34: Chicken quarters 3 | C34: Plate | D34: 10 | E34: =_xlfn.XLOOKUP('Meat Prep'!J6,'Meat Prep'!J6,'Meat Prep'!J6)*(D34/16) -> 0.63114569 | H34: 2 | I34: =H34*'Meat Recipes'!$F$27 -> 0.28886916 | J34: Macaroni and cheese | K34: =_xlfn.XLOOKUP(J34,$B$37:$B$45,$E$37:$E$45,"") -> 1.72375 | L34: Baked beans | M34: =_xlfn.XLOOKUP(L34,$B$37:$B$45,$E$37:$E$45,"") -> 0.45461538 | N34: =_xlfn.XLOOKUP(Packaging!B4,Packaging!B4,Packaging!E4) -> 0.2559 | O34: =SUM(E34,G34,I34,K34,M34,N34) -> 3.3542802
B35: Chicken quarters 4 | C35: Plate | D35: 10 | E35: =_xlfn.XLOOKUP('Meat Prep'!J6,'Meat Prep'!J6,'Meat Prep'!J6)*(D35/16) -> 0.63114569 | H35: 2 | I35: =H35*'Meat Recipes'!$F$27 -> 0.28886916 | J35: French fries | K35: =_xlfn.XLOOKUP(J35,$B$37:$B$45,$E$37:$E$45,"") -> 0.27303241 | L35: Coleslaw, Resers | M35: =_xlfn.XLOOKUP(L35,$B$37:$B$45,$E$37:$E$45,"") -> 1.0066071 | N35: =_xlfn.XLOOKUP(Packaging!B4,Packaging!B4,Packaging!E4) -> 0.2559 | O35: =SUM(E35,G35,I35,K35,M35,N35) -> 2.4555544
B37: Sides
B38: Corn Cobbetts | C38: Sides | D38: 1 | E38: =_xlfn.XLOOKUP(B38,Ingredients!B21,Ingredients!H21) -> 0.29298611
B39: French fries | C39: Sides | D39: 5 | E39: =_xlfn.XLOOKUP(B39,Ingredients!$B$10:$B$49,Ingredients!$H$10:$H$49)*D39 -> 0.27303241
B40: Baked beans | C40: Sides | D40: 6 | E40: =_xlfn.XLOOKUP(B40,Ingredients!$B$10:$B$49,Ingredients!$H$10:$H$49)*D40 -> 0.45461538
B41: Coleslaw, Resers | C41: Sides | D41: 6 | E41: =_xlfn.XLOOKUP(B41,Ingredients!$B$10:$B$49,Ingredients!$H$10:$H$49)*D41 -> 1.0066071
B42: Potato Salad, Resers | C42: Sides | D42: 6 | E42: =_xlfn.XLOOKUP(B42,Ingredients!$B$10:$B$49,Ingredients!$H$10:$H$49)*D42 -> 0.73546875
B43: Macaroni and cheese | C43: Sides | D43: 5 | E43: =_xlfn.XLOOKUP(B43,Ingredients!$B$10:$B$49,Ingredients!$H$10:$H$49)*D43 -> 1.72375
B46: Add ons
B47: Blackberry Cobbler | C47: Dessert | D47: 5 | E47: =_xlfn.XLOOKUP(B47,'Other recipes'!B2,'Other recipes'!F13) -> 1.0528344 | O47: =_xlfn.XLOOKUP(B47,'Other recipes'!B2,'Other recipes'!F13) -> 1.0528344
B48: Peach Cobbler | C48: Dessert | D48: 5 | E48: =_xlfn.XLOOKUP(B48,'Other recipes'!B15,'Other recipes'!F27) -> 1.0027788 | O48: =_xlfn.XLOOKUP(B48,'Other recipes'!B15,'Other recipes'!F27) -> 1.0027788
B49: Banana Pudding | C49: Dessert | D49: 5 | E49: =_xlfn.XLOOKUP(B49,'Other recipes'!B29,'Other recipes'!F35) -> 0.73480923 | O49: =_xlfn.XLOOKUP(B49,'Other recipes'!B29,'Other recipes'!F35) -> 0.73480923
B52: Sauce cups
...

Sheet Cost analysis
B2: Target Food Cost | C2: 0.3
B3: Menu Item | C3: Total Cost | D3: Suggested Price | E3: Actual/Chosen Price | F3: Gross Contribution | G3: Food Cost % | H3: Gross Margin
B4: Pulled Pork Sandwich | C4: =('Menu items'!O3) -> 1.7761977 | D4: =SUM(C4/$C$2) -> 5.9206591 | E4: 6 | F4: =SUM(E4-C4) -> 4.2238023 | G4: =SUM(C4/E4) -> 0.29603295 | H4: =(E4-C4)/E4 -> 0.70396705
B5: Pork Combo 1 | C5: =('Menu items'!O5) -> 2.0474722 | D5: =SUM(C5/$C$2) -> 6.8249074 | E5: 7 | F5: =SUM(E5-C5) -> 4.9525278 | G5: =SUM(C5/E5) -> 0.29249603 | H5: =(E5-C5)/E5 -> 0.70750397
B6: Pork Combo 2 | C6: =('Menu items'!O6) -> 3.0551573 | D6: =SUM(C6/$C$2) -> 10.183858 | E6: 13 | F6: =SUM(E6-C6) -> 9.9448427 | G6: =SUM(C6/E6) -> 0.2350121 | H6: =(E6-C6)/E6 -> 0.7649879
B7: Pork Combo 3 | C7: =('Menu items'!O7) -> 2.6126746 | D7: =SUM(C7/$C$2) -> 8.7089155 | E7: 13 | F7: =SUM(E7-C7) -> 10.387325 | G7: =SUM(C7/E7) -> 0.20097497 | H7: =(E7-C7)/E7 -> 0.79902503
B8: Pork Combo 4 | C8: =('Menu items'!O8) -> 3.1447127 | D8: =SUM(C8/$C$2) -> 10.482376 | E8: 13 | F8: =SUM(E8-C8) -> 9.8552873 | G8: =SUM(C8/E8) -> 0.24190098 | H8: =(E8-C8)/E8 -> 0.75809902
B9: Pork Plate 1 | C9: =('Menu items'!O9) -> 3.1443901 | D9: =SUM(C9/$C$2) -> 10.4813 | E9: 15 | F9: =SUM(E9-C9) -> 11.85561 | G9: =SUM(C9/E9) -> 0.209626 | H9: =(E9-C9)/E9 -> 0.790374
B10: Pork Plate 2 | C10: =('Menu items'!O10) -> 3.325973 | D10: =SUM(C10/$C$2) -> 11.086577 | E10: 15 | F10: =SUM(E10-C10) -> 11.674027 | G10: =SUM(C10/E10) -> 0.22173154 | H10: =(E10-C10)/E10 -> 0.77826846
B11: Pork Plate 3 | C11: =('Menu items'!O11) -> 4.3142543 | D11: =SUM(C11/$C$2) -> 14.380848 | E11: 15 | F11: =SUM(E11-C11) -> 10.685746 | G11: =SUM(C11/E11) -> 0.28761695 | H11: =(E11-C11)/E11 -> 0.71238305
B12: Pork Plate 4 | C12: =('Menu items'!O12) -> 3.4155285 | D12: =SUM(C12/$C$2) -> 11.385095 | E12: 15 | F12: =SUM(E12-C12) -> 11.584472 | G12: =SUM(C12/E12) -> 0.2277019 | H12: =(E12-C12)/E12 -> 0.7722981
B14: Brisket Sandwich | C14: =('Menu items'!O16) -> 3.6393099 | D14: =SUM(C14/$C$2) -> 12.131033 | E14: 13 | F14: =SUM(E14-C14) -> 9.3606901 | G14: =SUM(C14/E14) -> 0.27994691 | H14: =(E14-C14)/E14 -> 0.72005309
B15: Brisket combo 1 | C15: =('Menu items'!O18) -> 4.0550189 | D15: =SUM(C15/$C$2) -> 13.51673 | E15: 14 | F15: =SUM(E15-C15) -> 9.9449811 | G15: =SUM(C15/E15) -> 0.28964421 | H15: =(E15-C15)/E15 -> 0.71035579
B16: Brisket combo 2 | C16: =('Menu items'!O19) -> 5.062704 | D16: =SUM(C16/$C$2) -> 16.87568 | E16: 17 | F16: =SUM(E16-C16) -> 11.937296 | G16: =SUM(C16/E16) -> 0.29780612 | H16: =(E16-C16)/E16 -> 0.70219388
B17: Brisket combo 3 | C17: =('Menu items'!O20) -> 6.0509852 | D17: =SUM(C17/$C$2) -> 20.169951 | E17: 17 | F17: =SUM(E17-C17) -> 10.949015 | G17: =SUM(C17/E17) -> 0.35594031 | H17: =(E17-C17)/E17 -> 0.64405969
B18: Brisket combo 4 | C18: =('Menu items'!O21) -> 5.1522594 | D18: =SUM(C18/$C$2) -> 17.174198 | E18: 17 | F18: =SUM(E18-C18) -> 11.847741 | G18: =SUM(C18/E18) -> 0.30307408 | H18: =(E18-C18)/E18 -> 0.69692592
B19: Brisket plate 1 | C19: =('Menu items'!O22) -> 5.6766844 | D19: =SUM(C19/$C$2) -> 18.922281 | E19: 20 | F19: =SUM(E19-C19) -> 14.323316 | G19: =SUM(C19/E19) -> 0.28383422 | H19: =(E19-C19)/E19 -> 0.71616578
B20: Brisket plate 2 | C20: =('Menu items'!O23) -> 5.8582674 | D20: =SUM(C20/$C$2) -> 19.527558 | E20: 20 | F20: =SUM(E20-C20) -> 14.141733 | G20: =SUM(C20/E20) -> 0.29291337 | H20: =(E20-C20)/E20 -> 0.70708663
B21: Brisket plate 3 | C21: =('Menu items'!O24) -> 6.8465487 | D21: =SUM(C21/$C$2) -> 22.821829 | E21: 20 | F21: =SUM(E21-C21) -> 13.153451 | G21: =SUM(C21/E21) -> 0.34232743 | H21: =(E21-C21)/E21 -> 0.65767257
B22: Brisket plate 4 | C22: =('Menu items'!O25) -> 5.9478228 | D22: =SUM(C22/$C$2) -> 19.826076 | E22: 20 | F22: =SUM(E22-C22) -> 14.052177 | G22: =SUM(C22/E22) -> 0.29739114 | H22: =(E22-C22)/E22 -> 0.70260886
B24: Tri-tip plate 1 | C24: =('Menu items'!O27) -> 4.820263 | D24: =SUM(C24/$C$2) -> 16.067543 | E24: 16 | F24: =SUM(E24-C24) -> 11.179737 | G24: =SUM(C24/E24) -> 0.30126644 | H24: =(E24-C24)/E24 -> 0.69873356
B25: Tri-tip plate 2 | C25: =('Menu items'!O28) -> 5.001846 | D25: =SUM(C25/$C$2) -> 16.67282 | E25: 16 | F25: =SUM(E25-C25) -> 10.998154 | G25: =SUM(C25/E25) -> 0.31261538 | H25: =(E25-C25)/E25 -> 0.68738462
B26: Tri-tip plate 3 | C26: =('Menu items'!O29) -> 5.9901273 | D26: =SUM(C26/$C$2) -> 19.967091 | E26: 16 | F26: =SUM(E26-C26) -> 10.009873 | G26: =SUM(C26/E26) -> 0.37438295 | H26: =(E26-C26)/E26 -> 0.62561705
B27: Tri-tip plate 4 | C27: =('Menu items'!O30) -> 5.0914014 | D27: =SUM(C27/$C$2) -> 16.971338 | E27: 16 | F27: =SUM(E27-C27) -> 10.908599 | G27: =SUM(C27/E27) -> 0.31821259 | H27: =(E27-C27)/E27 -> 0.68178741
... B32: Chicken quarters plate 4 | C32: =('Menu items'!O35) -> 2.4555544 | D32: =SUM(C32/$C$2) -> 8.1851813 | E32: 10 | F32: =SUM(E32-C32) -> 7.5444456 | G32: =SUM(C32/E32) -> 0.24555544 | H32: =(E32-C32)/E32 -> 0.75444456
B34: Loaded pork fries | C34: =('Menu items'!O14) -> 2.1635279 | D34: =SUM(C34/$C$2) -> 7.2117598 | E34: 8 | F34: =SUM(E34-C34) -> 5.8364721 | G34: =SUM(C34/E34) -> 0.27044099 | H34: =(E34-C34)/E34 -> 0.72955901
B36: Blackberry Cobbler | C36: =('Menu items'!O47) -> 1.0528344 | D36: =SUM(C36/$C$2) -> 3.5094479 | E36: 5 | F36: =SUM(E36-C36) -> 3.9471656 | G36: =SUM(C36/E36) -> 0.21056687 | H36: =(E36-C36)/E36 -> 0.78943313
B37: Peach Cobbler | C37: =('Menu items'!O48) -> 1.0027788 | D37: =SUM(C37/$C$2) -> 3.3425961 | E37: 5 | F37: =SUM(E37-C37) -> 3.9972212 | G37: =SUM(C37/E37) -> 0.20055576 | H37: =(E37-C37)/E37 -> 0.79944424
B38: Banana Pudding | C38: =('Menu items'!O49) -> 0.73480923 | D38: =SUM(C38/$C$2) -> 2.4493641 | E38: 5 | F38: =SUM(E38-C38) -> 4.2651908 | G38: =SUM(C38/E38) -> 0.14696185 | H38: =(E38-C38)/E38 -> 0.85303815
B40: #2 Rub Sauce Cup | C40: =('Menu items'!O53) -> 0.25093187 | D40: =SUM(C40/$C$2) -> 0.83643957 | E40: 0.5 | F40: =SUM(E40-C40) -> 0.24906813 | G40: =SUM(C40/E40) -> 0.50186374 | H40: =(E40-C40)/E40 -> 0.49813626
